Workbook

Sheet Casos de Teste
A1: ID | B1: Título | C1: Tipo | D1: Requisito | E1: Prioridade | F1: Pré-condições | G1: Passos | H1: Dados de teste | I1: Resultado esperado | J1: Resultado obtido | K1: Status | L1: Automatizado | M1: Evidência | N1: Observações
A2: CT-LOGIN-01 | B2: Login com sucesso (Admin) | C2: Funcional (positivo) | D2: RF01 — Login e Perfis | E2: Alta | F2: Estar na tela de login do EscolaNotas, sem nenhum usuário logado | G2: 1) Preencher o campo "Usuário" 2) Preencher o campo "Senha" 3) Clicar em "Entrar" | H2: Usuário: admin Senha: admin123 | I2: O sistema autentica e abre o Dashboard, exibindo o nome "Administrador" e o perfil "Administrador" na barra lateral. | J2: Conforme esperado | K2: Passou | L2: Sim — login.cy.js
A3: CT-LOGIN-02 | B3: Login com senha incorreta | C3: Negativo | D3: RF01 — Login e Perfis | E3: Alta | F3: Estar na tela de login do EscolaNotas, sem nenhum usuário logado | G3: 1) Preencher o campo "Usuário" 2) Preencher o campo "Senha" 3) Clicar em "Entrar" | H3: Usuário: admin Senha: teste (incorreta) | I3: O sistema não autentica, permanece na tela de login e exibe "Usuário ou senha inválidos." | J3: Conforme esperado | K3: Passou | L3: Sim — login.cy.js
A4: CT-LOGIN-03 | B4: Login com o campo Senha vazio | C4: Negativo | D4: RF01 — Login e Perfis | E4: Média | F4: Estar na tela de login do EscolaNotas, sem nenhum usuário logado | G4: 1) Preencher o campo "Usuário" 2) Deixar o campo "Senha" em branco 3) Clicar em "Entrar" | H4: Usuário: admin Senha: (vazio) | I4: O sistema não autentica, permanece na tela de login e exibe "Preencha a senha." | J4: Conforme esperado | K4: Passou | L4: Sim — login.cy.js | N4: CORRIGIDO: o resultado esperado dizia "Preencha usuário e senha". O sistema tem 3 mensagens distintas; com o usuário preenchido e a senha vazia, a mensagem correta é "Preencha a senha."
A5: CT-LOGIN-04 | B5: Login com o campo Usuário vazio | C5: Negativo | D5: RF01 — Login e Perfis | E5: Média | F5: Estar na tela de login do EscolaNotas, sem nenhum usuário logado | G5: 1) Deixar o campo "Usuário" em branco 2) Preencher o campo "Senha" 3) Clicar em "Entrar" | H5: Usuário: (vazio) Senha: admin123 | I5: O sistema não autentica, permanece na tela de login e exibe "Preencha o usuário." | J5: — | K5: Não executado | L5: Não | N5: NOVO: cenário que faltava. O sistema tem mensagem própria para este caso.
A6: CT-LOGIN-05 | B6: Login com Usuário e Senha vazios | C6: Negativo | D6: RF01 — Login e Perfis | E6: Média | F6: Estar na tela de login do EscolaNotas, sem nenhum usuário logado | G6: 1) Deixar os dois campos em branco 2) Clicar em "Entrar" | H6: Usuário: (vazio) Senha: (vazio) | I6: O sistema não autentica, permanece na tela de login e exibe "Preencha usuário e senha." | J6: — | K6: Não executado | L6: Não | N6: NOVO: cenário que faltava. É este o caso que produz a mensagem que estava no CT-LOGIN-03.
A7: CT-AUTH-01 | B7: Permissão — Admin vê o menu completo | C7: Permissão (RBAC) | D7: RF01 — Login e Perfis | E7: Alta | F7: Estar na tela de login do EscolaNotas, sem nenhum usuário logado | G7: 1) Preencher o campo "Usuário" 2) Preencher o campo "Senha" 3) Clicar em "Entrar" 4) Observar o menu lateral | H7: Usuário: admin Senha: admin123 | I7: Abre o Dashboard com o perfil "Administrador". O menu lateral exibe as 9 opções: Dashboard, Alunos, Professores, Disciplinas, Turmas, Lançar Notas, Boletim, Relatórios e Requisitos. | J7: Conforme esperado | K7: Passou | L7: Sim — permissoes.cy.js | N7: ID padronizado (estava “CT- AUTH- 01”).
A8: CT-AUTH-02 | B8: Permissão — Coordenador não vê Professores e Disciplinas | C8: Permissão (RBAC) | D8: RF01 — Login e Perfis | E8: Alta | F8: Estar na tela de login do EscolaNotas, sem nenhum usuário logado | G8: 1) Preencher o campo "Usuário" 2) Preencher o campo "Senha" 3) Clicar em "Entrar" 4) Observar o menu lateral | H8: Usuário: coordenador Senha: coord123 | I8: Abre o Dashboard com o perfil "Coordenador". O menu exibe Dashboard, Alunos, Turmas, Lançar Notas, Boletim, Relatórios e Requisitos, e NÃO exibe Professores nem Disciplinas. | J8: Conforme esperado | K8: Passou | L8: Sim — permissoes.cy.js | N8: Acrescentado Requisitos à lista de menus permitidos.
A9: CT-AUTH-03 | B9: Permissão — Professor vê apenas os menus permitidos | C9: Permissão (RBAC) | D9: RF01 — Login e Perfis | E9: Alta | F9: Estar na tela de login do EscolaNotas, sem nenhum usuário logado | G9: 1) Preencher o campo "Usuário" 2) Preencher o campo "Senha" 3) Clicar em "Entrar" 4) Observar o menu lateral | H9: Usuário: professor Senha: prof123 | I9: Abre o Dashboard com o perfil "Professor". O menu exibe apenas Dashboard, Lançar Notas, Boletim e Requisitos, e NÃO exibe Alunos, Professores, Disciplinas, Turmas nem Relatórios. | J9: Conforme esperado | K9: Passou | L9: Sim — permissoes.cy.js | N9: CORRIGIDO: o resultado esperado omitia o menu Requisitos, que o perfil Professor também acessa.
A10: CT-ALUNO-01 | B10: Cadastro de aluno com sucesso | C10: Funcional (positivo) | D10: RF02 — Alunos | E10: Alta | F10: Estar logada como Admin, na tela de Alunos | G10: 1) Clicar em "+ Novo aluno" 2) Preencher os campos do formulário com a massa de teste 3) Clicar em "Salvar aluno" | H10: Nome completo: Teste de Oliveira Matrícula: 140325 CPF: 999.999.999-99 Data de nascimento: 14/03/2006 Turma: 1A Responsável: Teste Mãe de Oliveira Telefone: (11) 99999-9999 E-mail: teste@teste.com Status: Ativo | I10: O sistema exibe "Aluno cadastrado!" e o novo aluno passa a aparecer na lista "Alunos cadastrados". | J10: Conforme esperado | K10: Passou | L10: Sim — aluno.cy.js
A11: CT-ALUNO-02 | B11: Cadastro de aluno com matrícula duplicada | C11: Negativo | D11: RF02 — Alunos | E11: Alta | F11: Estar logada como Admin, na tela de Alunos. Usa a matrícula 2026001, do aluno "Ana Beatriz Souza" que já vem cadastrado no sistema. | G11: 1) Clicar em "+ Novo aluno" 2) Preencher os campos do formulário com a massa de teste 3) Clicar em "Salvar aluno" | H11: Nome completo: Testando Matrícula: 2026001 (já existente) CPF: 222.222.222-22 Data de nascimento: 10/08/2008 Turma: 2B Responsável: Testando Mãe Telefone: (11) 99999-9999 E-mail: testando@teste.com Status: Ativo | I11: O sistema não cadastra o aluno, destaca o campo Matrícula com "Matrícula numérica e única." e exibe o aviso "Corrija os campos destacados." | J11: Conforme esperado | K11: Passou | L11: Sim — aluno.cy.js | N11: CORRIGIDO: a pré-condição dependia do CT-ALUNO-01 ter rodado antes. Agora usa a massa que já vem no sistema, e o caso roda sozinho.
A12: CT-ALUNO-03 | B12: Cadastro de aluno com número no nome | C12: Exploratório | D12: RF02 — Alunos | E12: Baixa | F12: Estar logada como Admin, na tela de Alunos | G12: 1) Clicar em "+ Novo aluno" 2) Preencher os campos do formulário com a massa de teste 3) Clicar em "Salvar aluno" | H12: Nome completo: C12 Matrícula: 2131 CPF: 222.222.222-22 Data de nascimento: 10/08/2007 Turma: 2B Responsável: Testando Mãe Telefone: (11) 99999-9999 E-mail: teste@teste.com Status: Ativo | I12: Comportamento não especificado nos requisitos. O RF02 exige apenas nome obrigatório com mín. 3 caracteres, sem regra de formato. | J12: O sistema cadastrou normalmente e exibiu "Aluno cadastrado!" | K12: Pendente | L12: Sim — aluno.cy.js | N12: Lacuna de requisito, não defeito. Pergunta para o PO: o nome do aluno deve ter regra de formato? Prioridade rebaixada para Baixa por não haver regra violada.
A13: CT-ALUNO-04 | B13: Cadastro com nome de menos de 3 caracteres | C13: Negativo | D13: RF02 — Alunos | E13: Média | F13: Estar logada como Admin, na tela de Alunos | G13: 1) Clicar em "+ Novo aluno" 2) Preencher os campos do formulário com a massa de teste 3) Clicar em "Salvar aluno" | H13: Nome completo: Ts Matrícula: 9999 CPF: 123.456.789-10 Data de nascimento: 08/10/2006 Turma: 2B Responsável: Testando Mãe Telefone: (11) 99999-9999 E-mail: teste@teste.com Status: Ativo | I13: O sistema não cadastra o aluno, destaca o campo Nome completo com "Nome com pelo menos 3 caracteres." e exibe o aviso "Corrija os campos destacados." | J13: Conforme esperado | K13: Passou | L13: Sim — aluno.cy.js
A14: CT-ALUNO-05 | B14: Cadastro com matrícula não numérica | C14: Negativo | D14: RF02 — Alunos | E14: Média | F14: Estar logada como Admin, na tela de Alunos | G14: 1) Clicar em "+ Novo aluno" 2) Preencher os campos do formulário com a massa de teste 3) Clicar em "Salvar aluno" | H14: Nome completo: Teste Um Matrícula: 12Ma34 CPF: 999.999.999-99 Data de nascimento: 20/03/2010 Turma: 1A Responsável: Teste Mãe Telefone: (11) 99999-9999 E-mail: teste@teste.com Status: Ativo | I14: O sistema não cadastra o aluno, destaca o campo Matrícula com "Matrícula numérica e única." e exibe o aviso "Corrija os campos destacados." | J14: Conforme esperado | K14: Passou | L14: Sim — aluno.cy.js
A15: CT-ALUNO-06 | B15: Cadastro com CPF em formato incompleto | C15: Negativo | D15: RF02 — Alunos | E15: Média | F15: Estar logada como Admin, na tela de Alunos | G15: 1) Clicar em "+ Novo aluno" 2) Preencher os campos do formulário com a massa de teste 3) Clicar em "Salvar aluno" | H15: Nome completo: Teste Dois Matrícula: 1111 CPF: 123.456 Data de nascimento: 20/03/2010 Turma: 1A Responsável: Teste Mãe Telefone: (11) 99999-9999 E-mail: teste@teste.com Status: Ativo | I15: O sistema não cadastra o aluno, destaca o campo CPF com "CPF no formato 000.000.000-00." e exibe o aviso "Corrija os campos destacados." | J15: Conforme esperado | K15: Passou | L15: Sim — aluno.cy.js
A16: CT-ALUNO-07 | B16: Cadastro com e-mail em formato inválido | C16: Negativo | D16: RF02 — Alunos | E16: Média | F16: Estar logada como Admin, na tela de Alunos | G16: 1) Clicar em "+ Novo aluno" 2) Preencher os campos do formulário com a massa de teste 3) Clicar em "Salvar aluno" | H16: Nome completo: Teste Três Matrícula: 1234 CPF: 123.456.789-10 Data de nascimento: 20/03/2011 Turma: 1A Responsável: Teste Mãe Telefone: (11) 99999-9999 E-mail: teste%teste.com Status: Ativo | I16: O sistema não cadastra o aluno, destaca o campo E-mail com "E-mail obrigatório e válido." e exibe o aviso "Corrija os campos destacados." | J16: — | K16: Reexecutar | L16: Sim — aluno.cy.js | N16: CORRIGIDO: a massa tinha CPF 123.456, também inválido. Com dois campos inválidos não dá para saber qual regra reprovou o cadastro. CPF trocado por um válido — reexecutar. O teste automatizado já usava CPF válido: a divergência estava só na documentação manual.
A17: CT-ALUNO-08 | B17: Cadastro com telefone vazio | C17: Negativo | D17: RF02 — Alunos | E17: Média | F17: Estar logada como Admin, na tela de Alunos | G17: 1) Clicar em "+ Novo aluno" 2) Preencher os campos do formulário com a massa de teste 3) Clicar em "Salvar aluno" | H17: Nome completo: Teste Quatro Matrícula: 12345 CPF: 123.456.789-10 Data de nascimento: 20/03/2011 Turma: 1A Responsável: Teste Mãe Telefone: (vazio) E-mail: teste@teste.com Status: Ativo | I17: O sistema não cadastra o aluno, destaca o campo Telefone com "Telefone obrigatório no formato (00) 00000-0000." e exibe o aviso "Corrija os campos destacados." | J17: Conforme esperado | K17: Passou | L17: Sim — aluno.cy.js
A18: CT-ALUNO-09 | B18: Salvar o formulário com todos os campos vazios | C18: Negativo | D18: RF02 — Alunos | E18: Média | F18: Estar logada como Admin, na tela de Alunos | G18: 1) Clicar em "+ Novo aluno" 2) Não preencher nenhum campo 3) Clicar em "Salvar aluno" | H18: Todos os campos em branco. Obs.: o campo Status é uma lista que já vem com "Ativo" e não pode ficar vazio. | I18: O sistema não cadastra o aluno, destaca todos os campos obrigatórios e exibe o aviso "Corrija os campos destacados." | J18: Conforme esperado | K18: Passou | L18: Sim — aluno.cy.js | N18: CORRIGIDO: a massa dizia "Status: (vazio)", mas o campo é uma lista com valor padrão e não aceita vazio.
A19: CT-ALUNO-10 | B19: Cadastro sem selecionar a turma | C19: Negativo | D19: RF02 — Alunos | E19: Média | F19: Estar logada como Admin, na tela de Alunos | G19: 1) Clicar em "+ Novo aluno" 2) Preencher os campos do formulário com a massa de teste 3) Clicar em "Salvar aluno" | H19: Nome completo: Teste Cinco Matrícula: 123451 CPF: 123.456.789-10 Data de nascimento: 20/03/2011 Turma: (não selecionar) Responsável: Teste Mãe Telefone: (11) 99999-9999 E-mail: teste@teste.com Status: Ativo | I19: O sistema não cadastra o aluno, destaca o campo Turma com "Selecione uma turma." e exibe o aviso "Corrija os campos destacados." | J19: — | K19: Reexecutar | L19: Sim — aluno.cy.js | N19: CORRIGIDO: a massa também deixava o Telefone vazio, que é outro campo obrigatório. Telefone preenchido — reexecutar. O teste automatizado já preenchia o telefone: a divergência estava só na documentação manual.
A20: CT-ALUNO-11 | B20: Cadastro sem preencher o responsável | C20: Negativo | D20: RF02 — Alunos | E20: Média | F20: Estar logada como Admin, na tela de Alunos | G20: 1) Clicar em "+ Novo aluno" 2) Preencher os campos do formulário com a massa de teste 3) Clicar em "Salvar aluno" | H20: Nome completo: Teste Seis Matrícula: 123452 CPF: 123.456.789-10 Data de nascimento: 20/03/2010 Turma: 2B Responsável: (vazio) Telefone: (11) 99999-9999 E-mail: teste@teste.com Status: Ativo | I20: O sistema não cadastra o aluno, destaca o campo Responsável com "Informe o responsável." e exibe o aviso "Corrija os campos destacados." | J20: — | K20: Reexecutar | L20: Sim — aluno.cy.js | N20: CORRIGIDO: a massa também deixava o Telefone vazio. Além disso a turma estava escrita "2b" (minúscula); o valor correto é "2B". O teste automatizado já estava correto nos dois pontos.
A21: CT-ALUNO-12 | B21: Editar um aluno existente | C21: Funcional (positivo) | D21: RF02 — Alunos | E21: Alta | F21: Estar logada como Admin, na tela de Alunos, e existir o aluno "Ana Beatriz Souza" (matrícula 2026001). | G21: 1) Na lista de alunos, localizar "Ana Beatriz Souza" 2) Clicar em "Editar" na linha desse aluno 3) Alterar o Telefone para (11) 98888-7777 4) Clicar em "Salvar aluno" | H21: Aluno: Ana Beatriz Souza (matrícula 2026001) Campo alterado — Telefone: (11) 98888-7777 | I21: O sistema exibe "Aluno atualizado!" e a lista passa a mostrar o telefone atualizado, sem criar um registro novo — continua sendo o mesmo aluno, apenas com o dado alterado. | J21: Conforme esperado | K21: Passou | L21: Sim — aluno.cy.js
A22: CT-ALUNO-13 | B22: Excluir um aluno | C22: Funcional (positivo) | D22: RF02 — Alunos | E22: Alta | F22: Estar logada como Admin, na tela de Alunos, e existir o aluno "Carla Mendes" (matrícula 2026003). | G22: 1) Na lista de alunos, localizar "Carla Mendes" 2) Clicar em "Excluir" na linha desse aluno 3) No pop-up de confirmação, clicar em "Excluir" | H22: Aluno: Carla Mendes (matrícula 2026003) | I22: O sistema exibe "Aluno excluído." e "Carla Mendes" deixa de aparecer na lista. As notas do aluno também são removidas. | J22: Conforme esperado | K22: Passou | L22: Sim — aluno.cy.js
A23: CT-ALUNO-14 | B23: Editar aluno que está cadastrado sem e-mail | C23: Negativo | D23: RF02 — Alunos | E23: Alta | F23: Estar logada como Admin, na tela de Alunos. O aluno "Bruno Henrique Lima" (matrícula 2026002) já vem cadastrado no sistema sem e-mail. | G23: 1) Na lista de alunos, localizar "Bruno Henrique Lima" 2) Clicar em "Editar" 3) Alterar apenas o Telefone para (11) 91234-5678 4) Clicar em "Salvar aluno" | H23: Aluno: Bruno Henrique Lima (matrícula 2026002) Campo alterado — Telefone: (11) 91234-5678 | I23: O sistema deveria salvar a alteração do telefone, já que o aluno foi criado pelo próprio sistema nesse estado. | J23: O sistema bloqueia o salvamento, destaca o campo E-mail com "E-mail obrigatório e válido." e não grava a alteração. É impossível editar qualquer dado do aluno sem inventar um e-mail. | K23: Falhou | L23: Não | N23: NOVO — defeito confirmado. Ver aba Defeitos (BUG-01). Atinge as matrículas 2026002 e 2026004.
A24: CT-DISC-01 | B24: Cadastro de nova disciplina com sucesso | C24: Funcional (positivo) | D24: RF03 — Disciplinas e Professores | E24: Alta | F24: Estar logada como Admin, na tela de Disciplinas | G24: 1) Preencher os campos do formulário com a massa de teste 2) Clicar em "Salvar" | H24: Nome: Geografia Carga horária (h): 60 | I24: O sistema exibe "Disciplina cadastrada!" e a nova disciplina passa a aparecer na lista de Disciplinas. | J24: Conforme esperado | K24: Passou | L24: Sim — disc.cy.js | N24: CORRIGIDO: a carga era 70 aqui e 60 na pré-condição do CT-DISC-03. Padronizado em 60. Atenção: no disc.cy.js o teste correspondente está com o ID escrito "CT-DSIC-01" (letras trocadas) — corrigir na próxima vez que mexer no arquivo.
A25: CT-DISC-02 | B25: Cadastro de disciplina com o nome vazio | C25: Negativo | D25: RF03 — Disciplinas e Professores | E25: Média | F25: Estar logada como Admin, na tela de Disciplinas | G25: 1) Deixar o campo "Nome" em branco 2) Preencher a Carga horária 3) Clicar em "Salvar" | H25: Nome: (vazio) Carga horária (h): 70 | I25: O sistema não cadastra a disciplina, destaca o campo Nome com "Nome obrigatório." e exibe o aviso "Corrija os campos." | J25: Conforme esperado | K25: Passou | L25: Sim — disc.cy.js
A26: CT-DISC-03 | B26: Editar uma disciplina com sucesso | C26: Funcional (positivo) | D26: RF03 — Disciplinas e Professores | E26: Alta | F26: Estar logada como Admin, na tela de Disciplinas, e existir a disciplina "Geografia" com 60h. | G26: 1) Localizar "Geografia" na lista 2) Clicar em "Editar" 3) Alterar a Carga horária para 80 4) Clicar em "Salvar" | H26: Disciplina: Geografia Campo alterado — Carga horária: 80 | I26: O sistema exibe "Disciplina atualizada!" e a lista passa a mostrar 80h para Geografia, sem criar um registro novo. | J26: Conforme esperado | K26: Passou | L26: Sim — disc.cy.js | N26: CORRIGIDO: a massa dizia "80h". O "h" é só como o sistema exibe na lista; no campo digita-se apenas o número.
A27: CT-DISC-04 | B27: Excluir uma disciplina com sucesso | C27: Funcional (positivo) | D27: RF03 — Disciplinas e Professores | E27: Alta | F27: Estar logada como Admin, na tela de Disciplinas, e existir a disciplina "Espanhol" sem professores vinculados. | G27: 1) Localizar "Espanhol" na lista 2) Clicar em "Excluir" 3) Confirmar a exclusão | H27: Disciplina: Espanhol | I27: O sistema exibe "Disciplina excluída." e "Espanhol" deixa de aparecer na lista de disciplinas. | J27: Conforme esperado | K27: Passou | L27: Sim — disc.cy.js
A28: CT-DISC-05 | B28: Cadastro de disciplina com a carga horária vazia | C28: Negativo | D28: RF03 — Disciplinas e Professores | E28: Média | F28: Estar logada como Admin, na tela de Disciplinas | G28: 1) Preencher o campo "Nome" 2) Deixar a Carga horária em branco 3) Clicar em "Salvar" | H28: Nome: Geografia Carga horária (h): (vazio) | I28: O sistema não cadastra a disciplina, destaca o campo Carga horária com "Carga horária numérica maior que 0." e exibe o aviso "Corrija os campos." | J28: Conforme esperado | K28: Passou | L28: Sim — disc.cy.js
A29: CT-DISC-06 | B29: Cadastro de disciplina com números no nome | C29: Exploratório | D29: RF03 — Disciplinas e Professores | E29: Baixa | F29: Estar logada como Admin, na tela de Disciplinas | G29: 1) Preencher os campos do formulário com a massa de teste 2) Clicar em "Salvar" | H29: Nome: 123 Carga horária (h): 70 | I29: Comportamento não especificado nos requisitos. O RF03 exige apenas nome obrigatório, sem regra de formato ou tamanho mínimo. | J29: O sistema cadastrou normalmente e exibiu "Disciplina cadastrada!" | K29: Pendente | L29: Sim — disc.cy.js | N29: CORRIGIDO: o resultado esperado dizia "não deve permitir o cadastro", mas nenhum requisito proíbe números no nome — logo não é defeito, e sim lacuna de requisito. Mesmo tratamento dado ao CT-ALUNO-03.
A30: CT-DISC-07 | B30: Formulário de edição continua ativo após excluir a disciplina em edição | C30: Negativo | D30: RF03 — Disciplinas e Professores | E30: Média | F30: Estar logada como Admin, na tela de Disciplinas, com a disciplina "História" cadastrada. | G30: 1) Clicar em "Editar" na disciplina "História" 2) Conferir que o formulário abre preenchido, com o título "Editar disciplina" 3) Sem sair da edição, clicar em "Excluir" na linha da mesma disciplina 4) Confirmar a exclusão 5) Alterar a Carga horária e clicar em "Salvar" | H30: Disciplina: História (60h) Campo alterado após a exclusão — Carga horária: 99 | I30: Ao excluir o registro que está em edição, o sistema deveria limpar ou fechar o formulário, impedindo a edição de algo que não existe mais. | J30: O formulário permanece preenchido e com o título "Editar disciplina". Ao clicar em "Salvar", a aplicação lança a exceção "TypeError: Cannot set properties of undefined (setting 'nome')" e nada é gravado. Na tela não aparece confirmação nem mensagem de erro: para o usuário, a falha é silenciosa. | K30: Falhou | L30: Não | N30: Defeito confirmado. Ver aba Defeitos (BUG-02). Tipo alterado de Exploratório para Negativo: há falha funcional, não apenas comportamento não especificado. Resultado obtido detalhado após execução automatizada, que expôs a exceção de JavaScript por trás da falha silenciosa.
A31: CT-DISC-08 | B31: Cadastro com carga horária igual a zero | C31: Negativo | D31: RF03 — Disciplinas e Professores | E31: Média | F31: Estar logada como Admin, na tela de Disciplinas | G31: 1) Preencher os campos do formulário com a massa de teste 2) Clicar em "Salvar" | H31: Nome: Matemática Carga horária (h): 0 | I31: O sistema não cadastra a disciplina, destaca o campo Carga horária com "Carga horária numérica maior que 0." e exibe o aviso "Corrija os campos." | J31: Conforme esperado | K31: Passou | L31: Não | N31: CORRIGIDO: o aviso esperado era "Corrija os campos destacados." Na tela de Disciplinas o sistema exibe "Corrija os campos."
A32: CT-DISC-09 | B32: Cadastro com carga horária negativa | C32: Negativo | D32: RF03 — Disciplinas e Professores | E32: Média | F32: Estar logada como Admin, na tela de Disciplinas | G32: 1) Preencher os campos do formulário com a massa de teste 2) Clicar em "Salvar" | H32: Nome: Espanhol Carga horária (h): -25 | I32: O sistema não cadastra a disciplina, destaca o campo Carga horária com "Carga horária numérica maior que 0." e exibe o aviso "Corrija os campos." | J32: Conforme esperado | K32: Passou | L32: Não | N32: CORRIGIDO: mesmo ajuste de mensagem do CT-DISC-08.
A33: CT-DISC-10 | B33: Cadastro com letras na carga horária | C33: Negativo | D33: RF03 — Disciplinas e Professores | E33: Média | F33: Estar logada como Admin, na tela de Disciplinas | G33: 1) Preencher os campos do formulário com a massa de teste 2) Clicar em "Salvar" | H33: Nome: Inglês Carga horária (h): 1a2 | I33: O sistema não cadastra a disciplina, destaca o campo Carga horária com "Carga horária numérica maior que 0." e exibe o aviso "Corrija os campos." | J33: Conforme esperado | K33: Passou | L33: Não | N33: CORRIGIDO: mesmo ajuste de mensagem do CT-DISC-08.
A34: CT-DISC-11 | B34: Cadastro com carga horária decimal | C34: Exploratório | D34: RF03 — Disciplinas e Professores | E34: Baixa | F34: Estar logada como Admin, na tela de Disciplinas | G34: 1) Preencher os campos do formulário com a massa de teste 2) Clicar em "Salvar" | H34: Nome: Física Carga horária (h): 70.5 | I34: Comportamento não especificado nos requisitos. O RF03 exige apenas carga horária numérica maior que 0, sem dizer se aceita decimal. | J34: O campo aceita a digitação de "70.5" normalmente. Ao salvar, o sistema recusa o cadastro com "Carga horária numérica maior que 0." e a disciplina não é criada. | K34: Pendente | L34: Não | N34: CORRIGIDO: o resultado obtido dizia que o sistema não permite digitar o ponto. Verificado: o campo é texto livre e aceita o ponto; a recusa acontece só na validação ao salvar. Pergunta para o PO: carga horária deve aceitar decimal?
A35: CT-DISC-12 | B35: Cadastro com caractere especial no nome | C35: Exploratório | D35: RF03 — Disciplinas e Professores | E35: Baixa | F35: Estar logada como Admin, na tela de Disciplinas | G35: 1) Preencher os campos do formulário com a massa de teste 2) Clicar em "Salvar" | H35: Nome: Quí%mica Carga horária (h): 50 | I35: Comportamento não especificado nos requisitos. O RF03 não define regra de formato para o nome. | J35: O sistema cadastrou normalmente e exibiu "Disciplina cadastrada!" | K35: Pendente | L35: Não | N35: Mesma lacuna de requisito do CT-DISC-06. Vale levar as duas juntas ao PO.
A36: CT-DISC-13 | B36: Excluir disciplina vinculada a um professor | C36: Negativo | D36: RF03 — Disciplinas e Professores | E36: Alta | F36: Estar logada como Admin. Existir a disciplina "Matemática" e o professor "Teste A" vinculado apenas a ela. | G36: 1) Ir para a tela de Disciplinas 2) Localizar "Matemática" e clicar em "Excluir" 3) Confirmar a exclusão 4) Ir para a tela de Professores 5) Localizar "Teste A" e observar a coluna Disciplinas | H36: Disciplina: Matemática Professor vinculado: Teste A | I36: O sistema deveria avisar que existe professor vinculado ou impedir a exclusão, já que o RF03 exige ao menos 1 disciplina por professor. | J36: A disciplina é excluída sem nenhum aviso. Na lista de Professores, "Teste A" passa a exibir um traço ("—") no lugar da disciplina, ficando sem nenhuma disciplina válida e violando a regra do próprio requisito. O efeito atinge todos os professores ligados à disciplina: "Carlos Pereira", que já vem cadastrado, passou a exibir "— Ciências". | K36: Falhou | L36: Não | N36: Defeito confirmado. Ver aba Defeitos (BUG-03). Resultado obtido detalhado após verificação: o vínculo não é removido, fica apontando para uma disciplina inexistente.
A37: CT-PROF-01 | B37: Cadastro de professor com sucesso | C37: Funcional (positivo) | D37: RF03 — Disciplinas e Professores | E37: Alta | F37: Estar logada como Admin, na tela de Professores, com ao menos uma disciplina cadastrada | G37: 1) Preencher o campo "Nome" 2) Preencher o campo "E-mail" 3) Marcar ao menos uma disciplina em "Disciplinas que leciona" 4) Clicar em "Salvar" | H37: Nome: Teste A E-mail: teste@teste.com Disciplinas que leciona: Português | I37: O sistema exibe "Professor cadastrado!" e o novo professor passa a aparecer na lista de Professores. | J37: Conforme esperado | K37: Passou | L37: Não | N37: CORRIGIDO: nome alterado de "Teste" para "Teste A", que é o professor usado como pré-condição nos CT-PROF-06 e 07. Pré-condição passou a exigir disciplina cadastrada, sem a qual não há o que marcar.
A38: CT-PROF-02 | B38: Cadastro de professor com nome de menos de 3 caracteres | C38: Negativo | D38: RF03 — Disciplinas e Professores | E38: Média | F38: Estar logada como Admin, na tela de Professores, com ao menos uma disciplina cadastrada | G38: 1) Preencher o campo "Nome" 2) Preencher o campo "E-mail" 3) Marcar uma disciplina 4) Clicar em "Salvar" | H38: Nome: Pr E-mail: teste@teste.com Disciplinas que leciona: Inglês | I38: O sistema não cadastra o professor, destaca o campo Nome com "Nome obrigatório (mín. 3)." e exibe o aviso "Corrija os campos." | J38: Conforme esperado | K38: Passou | L38: Não | N38: CORRIGIDO: o aviso esperado era "Corrija os campos destacados." Na tela de Professores o sistema exibe "Corrija os campos."
A39: CT-PROF-03 | B39: Cadastro de professor com e-mail inválido | C39: Negativo | D39: RF03 — Disciplinas e Professores | E39: Média | F39: Estar logada como Admin, na tela de Professores, com ao menos uma disciplina cadastrada | G39: 1) Preencher o campo "Nome" 2) Preencher o campo "E-mail" 3) Marcar uma disciplina 4) Clicar em "Salvar" | H39: Nome: Teste B E-mail: teste%teste.com Disciplinas que leciona: Espanhol | I39: O sistema não cadastra o professor, destaca o campo E-mail com "E-mail válido obrigatório." e exibe o aviso "Corrija os campos." | J39: Conforme esperado | K39: Passou | L39: Não | N39: CORRIGIDO: mesmo ajuste de mensagem do CT-PROF-02. Nome trocado para "Teste B" para não colidir com o professor do CT-PROF-01.
A40: CT-PROF-04 | B40: Cadastro de professor sem selecionar disciplina | C40: Negativo | D40: RF03 — Disciplinas e Professores | E40: Média | F40: Estar logada como Admin, na tela de Professores, com ao menos uma disciplina cadastrada | G40: 1) Preencher o campo "Nome" 2) Preencher o campo "E-mail" 3) Não marcar nenhuma disciplina 4) Clicar em "Salvar" | H40: Nome: Teste C E-mail: teste@teste.com Disciplinas que leciona: (nenhuma marcada) | I40: O sistema não cadastra o professor, destaca o bloco Disciplinas que leciona com "Selecione pelo menos uma disciplina." e exibe o aviso "Corrija os campos." | J40: Conforme esperado | K40: Passou | L40: Não | N40: CORRIGIDO: mesmo ajuste de mensagem do CT-PROF-02.
...

Sheet Resumo
A1: Resumo da execução — Sistema EscolaNotas
A2: Todos os números abaixo são fórmulas que leem a aba 'Casos de Teste'. Ao atualizar um status lá, o resumo se atualiza sozinho.
A4: Status | B4: Qtde | C4: %
A5: Passou | B5: =COUNTIF('Casos de Teste'!$K$2:$K$43,A5) -> 30 | C5: =IFERROR(B5/$B$10,0) -> 0.71428571
A6: Falhou | B6: =COUNTIF('Casos de Teste'!$K$2:$K$43,A6) -> 3 | C6: =IFERROR(B6/$B$10,0) -> 0.071428571
A7: Pendente | B7: =COUNTIF('Casos de Teste'!$K$2:$K$43,A7) -> 4 | C7: =IFERROR(B7/$B$10,0) -> 0.095238095
A8: Reexecutar | B8: =COUNTIF('Casos de Teste'!$K$2:$K$43,A8) -> 3 | C8: =IFERROR(B8/$B$10,0) -> 0.071428571
A9: Não executado | B9: =COUNTIF('Casos de Teste'!$K$2:$K$43,A9) -> 2 | C9: =IFERROR(B9/$B$10,0) -> 0.047619048
A10: Total | B10: =SUM(B5:B9) -> 42 | C10: =IFERROR(B10/$B$10,0) -> 1
A12: Tipo de teste | B12: Qtde | C12: %
A13: Funcional (positivo) | B13: =COUNTIF('Casos de Teste'!$C$2:$C$43,A13) -> 10 | C13: =IFERROR(B13/$B$17,0) -> 0.23809524
A14: Negativo | B14: =COUNTIF('Casos de Teste'!$C$2:$C$43,A14) -> 25 | C14: =IFERROR(B14/$B$17,0) -> 0.5952381
A15: Permissão (RBAC) | B15: =COUNTIF('Casos de Teste'!$C$2:$C$43,A15) -> 3 | C15: =IFERROR(B15/$B$17,0) -> 0.071428571
A16: Exploratório | B16: =COUNTIF('Casos de Teste'!$C$2:$C$43,A16) -> 4 | C16: =IFERROR(B16/$B$17,0) -> 0.095238095
A17: Total | B17: =SUM(B13:B16) -> 42 | C17: =IFERROR(B17/$B$17,0) -> 1
A19: Prioridade | B19: Qtde | C19: %
A20: Alta | B20: =COUNTIF('Casos de Teste'!$E$2:$E$43,A20) -> 17 | C20: =IFERROR(B20/$B$23,0) -> 0.4047619
A21: Média | B21: =COUNTIF('Casos de Teste'!$E$2:$E$43,A21) -> 21 | C21: =IFERROR(B21/$B$23,0) -> 0.5
A22: Baixa | B22: =COUNTIF('Casos de Teste'!$E$2:$E$43,A22) -> 4 | C22: =IFERROR(B22/$B$23,0) -> 0.095238095
A23: Total | B23: =SUM(B20:B22) -> 42 | C23: =IFERROR(B23/$B$23,0) -> 1
A25: Automação | B25: Qtde | C25: %
A26: Automatizado | B26: =COUNTIF('Casos de Teste'!$L$2:$L$43,"Sim*") -> 25 | C26: =IFERROR(B26/$B$28,0) -> 0.5952381
A27: Ainda não automatizado | B27: =COUNTIF('Casos de Teste'!$L$2:$L$43,"Não") -> 17 | C27: =IFERROR(B27/$B$28,0) -> 0.4047619
A28: Total | B28: =SUM(B26:B27) -> 42 | D28: A matriz manual é maior que a automação de propósito: automatiza-se o que é repetitivo e estável, não tudo.
A30: Cobertura por requisito | B30: Casos | D30: Situação
A31: RF01 — Login e Perfis | B31: =COUNTIF('Casos de Teste'!$D$2:$D$43,A31) -> 8 | D31: Coberto — login, mensagens de campo vazio e RBAC dos 3 perfis
A32: RF02 — Alunos | B32: =COUNTIF('Casos de Teste'!$D$2:$D$43,A32) -> 14 | D32: Coberto — cadastro, validações de campo, edição e exclusão
A33: RF03 — Disciplinas e Professores | B33: =COUNTIF('Casos de Teste'!$D$2:$D$43,A33) -> 20 | D33: Coberto — disciplinas e professores
A34: RF04 — Turmas | B34: =COUNTIF('Casos de Teste'!$D$2:$D$43,A34) -> 0 | D34: SEM COBERTURA — nenhum caso escrito
A35: RF05 — Lançamento de notas | B35: =COUNTIF('Casos de Teste'!$D$2:$D$43,A35) -> 0 | D35: SEM COBERTURA — nenhum caso escrito
A36: RF06 — Situação por disciplina | B36: =COUNTIF('Casos de Teste'!$D$2:$D$43,A36) -> 0 | D36: SEM COBERTURA — nenhum caso escrito
A37: RF07 — Situação geral do aluno | B37: =COUNTIF('Casos de Teste'!$D$2:$D$43,A37) -> 0 | D37: SEM COBERTURA — nenhum caso escrito
A38: RF08 — Boletim e relatórios | B38: =COUNTIF('Casos de Teste'!$D$2:$D$43,A38) -> 0 | D38: SEM COBERTURA — nenhum caso escrito

Sheet Defeitos
A1: ID | B1: Título | C1: Caso de teste | D1: Requisito | E1: Severidade | F1: Prioridade | G1: Passos para reproduzir | H1: Resultado esperado | I1: Resultado obtido | J1: Análise / impacto | K1: Evidência
A2: BUG-01 | B2: Aluno cadastrado sem e-mail não pode ser editado | C2: CT-ALUNO-14 | D2: RF02 — Alunos | E2: Média | F2: Média | G2: 1) Logar como Admin e ir para Alunos 2) Localizar "Bruno Henrique Lima" (matrícula 2026002), que já vem no sistema sem e-mail 3) Clicar em "Editar" 4) Alterar apenas o Telefone 5) Clicar em "Salvar aluno" | H2: A alteração do telefone é salva normalmente. | I2: O sistema bloqueia o salvamento com "E-mail obrigatório e válido." e não grava nada. Nenhum dado do aluno pode ser alterado sem que se invente um e-mail inexistente. | J2: Os dados que já vêm no sistema violam a regra de validação que o próprio sistema aplica. Atinge as matrículas 2026002 (Bruno Henrique Lima) e 2026004 (Diego Alves), ambas sem e-mail.
A3: BUG-02 | B3: Formulário de edição continua ativo após a disciplina ser excluída | C3: CT-DISC-07 | D3: RF03 — Disciplinas e Professores | E3: Alta | F3: Média | G3: 1) Logar como Admin e ir para Disciplinas 2) Clicar em "Editar" numa disciplina 3) Sem sair da edição, clicar em "Excluir" na mesma disciplina e confirmar 4) Alterar a carga horária e clicar em "Salvar" | H3: Ao excluir o registro em edição, o formulário deveria ser limpo ou fechado. | I3: O formulário continua preenchido e com o título "Editar disciplina". Ao salvar, a aplicação lança "TypeError: Cannot set properties of undefined (setting 'nome')" e a alteração não é gravada. A exceção não aparece para o usuário: na tela não há confirmação nem mensagem de erro. | J3: Causa raiz: ao excluir, o sistema não limpa a variável que guarda o id do registro em edição. Na hora de salvar, a busca por esse id retorna undefined e o código tenta escrever numa referência inexistente, lançando a exceção. Severidade Alta por ser exceção não tratada com perda silenciosa de dado: o usuário acredita ter salvo algo que nunca foi gravado. Prioridade Média porque depende de uma sequência pouco frequente (excluir o registro que está aberto em edição) e é contornável recarregando a página.
A4: BUG-03 | B4: Excluir disciplina não remove o vínculo com o professor | C4: CT-DISC-13 | D4: RF03 — Disciplinas e Professores | E4: Alta | F4: Alta | G4: 1) Logar como Admin e cadastrar o professor "Teste A" vinculado apenas a "Matemática" 2) Ir para Disciplinas e excluir "Matemática" 3) Confirmar a exclusão 4) Voltar para Professores e observar a linha de "Teste A" | H4: O sistema deveria impedir a exclusão ou avisar que existe professor vinculado, já que o RF03 exige ao menos 1 disciplina por professor. | I4: A exclusão acontece sem aviso. O professor passa a exibir "—" na coluna Disciplinas, ficando sem nenhuma disciplina válida. Atinge todos os professores vinculados, não só o criado para o teste: "Carlos Pereira", do cadastro inicial, passou a exibir "— Ciências". | J4: Quebra de integridade referencial: o vínculo continua apontando para um registro que não existe mais. O sistema já faz essa limpeza para Turmas, mas não para Professores — a inconsistência sugere esquecimento na implementação.

Sheet Legenda
A1: Como usar esta planilha
A4: Status
A5: Passou | B5: O resultado obtido bateu com o resultado esperado.
A6: Falhou | B6: O sistema violou um requisito. Deve existir um defeito registrado na aba Defeitos.
A7: Pendente | B7: Teste exploratório cujo comportamento não está definido em requisito. Aguarda resposta do PO — não é defeito até que a regra exista.
A8: Reexecutar | B8: A massa de teste foi corrigida nesta revisão. O caso precisa ser executado de novo para que o resultado valha.
A9: Não executado | B9: Caso escrito, ainda não executado.
A10: Bloqueado | B10: Não foi possível executar (ambiente fora do ar, pré-condição impossível, defeito impedindo o fluxo).
A12: Prioridade
A13: Alta | B13: Fluxo crítico ou regra que protege a integridade dos dados: login, permissões, cadastro, edição, exclusão, unicidade.
A14: Média | B14: Validação de formato de campo. Erra o dado, mas não derruba o fluxo nem corrompe registro.
A15: Baixa | B15: Exploratório de baixo impacto e lacunas de requisito sem efeito prático imediato.
A17: Tipo
A18: Funcional (positivo) | B18: Caminho feliz: dados válidos, sistema deve aceitar.
A19: Negativo | B19: Quebra uma regra documentada de propósito. Exige um requisito explícito para ser violado.
A20: Permissão (RBAC) | B20: Verifica o que cada perfil pode e não pode acessar.
A21: Exploratório | B21: Investigação além do requisito. O resultado esperado é 'não especificado' — vira pergunta ao PO, não defeito.
A23: Coluna Observações | B23: Em vermelho e itálico: o que foi corrigido nesta revisão e por quê.
A24: Coluna Evidência | B24: Cole aqui o link do print ou do vídeo da execução. Um caso 'Falhou' sem evidência é difícil de defender.
